<?xml version="1.0" ?>
<!-- =================================================================================== -->
<!-- |    This document was autogenerated by xacro from create_2.urdf.xacro            | -->
<!-- |    EDITING THIS FILE BY HAND IS NOT RECOMMENDED                                 | -->
<!-- =================================================================================== -->
<robot name="create_2">
  <material name="green">
    <color rgba="0 0.8 0 1"/>
  </material>
  <link name="base_footprint">
    <visual>
      <origin rpy="0 0 0" xyz="0 0 0"/>
      <geometry>
        <box size="0.001 0.001 0.001"/>
      </geometry>
      <material name="green"/>
    </visual>
    <collision>
      <origin rpy="0 0 0" xyz="0 0 0.017"/>
      <geometry>
        <box size="0.001 0.001 0.001"/>
      </geometry>
    </collision>
  </link>
  <link name="base_link">
    <inertial>
      <mass value="2"/>
      <origin xyz="0 0 0.0"/>
      <inertia ixx="0.01" ixy="0.0" ixz="0.0" iyy="0.01" iyz="0.0" izz="0.5"/>
    </inertial>
    <visual>
      <origin rpy="0 0 0" xyz=" 0 0 0.0308"/>
      <geometry>
        <mesh filename="package://create_description/meshes/create_2.dae"/>
      </geometry>
    </visual>
    <collision>
      <origin rpy="0 0 0" xyz="0.0 0.0 0.0308"/>
      <geometry>
        <cylinder length="0.0611632" radius="0.16495"/>
      </geometry>
    </collision>
  </link>
  <link name="wall_sensor_link">
    <inertial>
      <mass value="0.01"/>
      <origin xyz="0 0 0"/>
      <inertia ixx="0.001" ixy="0.0" ixz="0.0" iyy="0.001" iyz="0.0" izz="0.001"/>
    </inertial>
  </link>
  <link name="left_cliff_sensor_link">
    <inertial>
      <mass value="0.01"/>
      <origin xyz="0 0 0"/>
      <inertia ixx="0.001" ixy="0.0" ixz="0.0" iyy="0.001" iyz="0.0" izz="0.001"/>
    </inertial>
  </link>
  <link name="right_cliff_sensor_link">
    <inertial>
      <mass value="0.01"/>
      <origin xyz="0 0 0"/>
      <inertia ixx="0.001" ixy="0.0" ixz="0.0" iyy="0.001" iyz="0.0" izz="0.001"/>
    </inertial>
  </link>
  <link name="leftfront_cliff_sensor_link">
    <inertial>
      <mass value="0.01"/>
      <origin xyz="0 0 0"/>
      <inertia ixx="1.0" ixy="0.0" ixz="0.0" iyy="0.01" iyz="0.0" izz="0.01"/>
    </inertial>
  </link>
  <link name="rightfront_cliff_sensor_link">
    <inertial>
      <mass value="0.01"/>
      <origin xyz="0 0 0"/>
      <inertia ixx="0.001" ixy="0.0" ixz="0.0" iyy="0.001" iyz="0.0" izz="0.001"/>
    </inertial>
  </link>
  <joint name="base_footprint_joint" type="fixed">
    <origin rpy="0 0 0" xyz="0 0 0.017"/>
    <parent link="base_footprint"/>
    <child link="base_link"/>
  </joint>
  <joint name="base_wall_sensor_joint" type="fixed">
    <origin rpy="0 0 -1.0" xyz="0.09 -0.120 0.042"/>
    <parent link="base_link"/>
    <child link="wall_sensor_link"/>
  </joint>
  <joint name="base_left_cliff_sensor_joint" type="fixed">
    <origin rpy="0 1.5707963267948966 0" xyz="0.07 0.14 0.01"/>
    <parent link="base_link"/>
    <child link="left_cliff_sensor_link"/>
  </joint>
  <joint name="base_right_cliff_sensor_joint" type="fixed">
    <origin rpy="0 1.5707963267948966 0" xyz="0.07 -0.14 0.01"/>
    <parent link="base_link"/>
    <child link="right_cliff_sensor_link"/>
  </joint>
  <joint name="base_leftfront_cliff_sensor_joint" type="fixed">
    <origin rpy="0 1.5707963267948966 0" xyz="0.15 0.04 0.01"/>
    <parent link="base_link"/>
    <child link="leftfront_cliff_sensor_link"/>
  </joint>
  <joint name="base_rightfront_cliff_sensor_joint" type="fixed">
    <origin rpy="0 1.5707963267948966 0" xyz="0.15 -0.04 0.01"/>
    <parent link="base_link"/>
    <child link="rightfront_cliff_sensor_link"/>
  </joint>
  <link name="left_wheel_link">
    <inertial>
      <origin xyz="0 0 0"/>
      <mass value="0.01"/>
      <inertia ixx="0.001" ixy="0.0" ixz="0.0" iyy="0.001" iyz="0.0" izz="0.001"/>
    </inertial>
    <visual>
      <origin rpy="0 1.5707963267948966 1.5707963267948966" xyz="0 0 0"/>
      <geometry>
        <cylinder length="0.024" radius="0.036"/>
      </geometry>
    </visual>
    <collision>
      <origin rpy="0 1.5707963267948966 1.5707963267948966" xyz="0 0 0"/>
      <geometry>
        <cylinder length="0.024" radius="0.036"/>
      </geometry>
    </collision>
  </link>
  <joint name="left_wheel_joint" type="continuous">
    <origin rpy="0 0 0" xyz="0 0.1175 0.015"/>
    <parent link="base_link"/>
    <child link="left_wheel_link"/>
    <axis xyz="0 1 0"/>
  </joint>
  <link name="right_wheel_link">
    <inertial>
      <origin xyz="0 0 0"/>
      <mass value="0.01"/>
      <inertia ixx="0.001" ixy="0.0" ixz="0.0" iyy="0.001" iyz="0.0" izz="0.001"/>
    </inertial>
    <visual>
      <origin rpy="0 1.5707963267948966 1.5707963267948966" xyz="0 0 0"/>
      <geometry>
        <cylinder length="0.024" radius="0.036"/>
      </geometry>
    </visual>
    <collision>
      <origin rpy="0 1.5707963267948966 1.5707963267948966" xyz="0 0 0"/>
      <geometry>
        <cylinder length="0.024" radius="0.036"/>
      </geometry>
    </collision>
  </link>
  <joint name="right_wheel_joint" type="continuous">
    <origin rpy="0 0 0" xyz="0 -0.1175 0.015"/>
    <parent link="base_link"/>
    <child link="right_wheel_link"/>
    <axis xyz="0 1 0"/>
  </joint>
  <!-- bumper sensor link -->
  <link name="bumper_link">
    <collision name="bumper_link_collision">
      <origin rpy="0 0 0" xyz="0 0 0"/>
      <geometry>
        <mesh filename="package://create_description/meshes/bumper_2.dae"/>
      </geometry>
    </collision>
  </link>
  <joint name="bumper_joint" type="fixed">
    <origin rpy="0 0 0" xyz="-0.0025 0 0"/>
    <parent link="base_link"/>
    <child link="bumper_link"/>
    <axis xyz="0 0 0"/>
  </joint>
  <!-- omni_ir sensor link -->
  <link name="omni_ir_link">
    </link>
  <joint name="omni_ir_joint" type="fixed">
    <origin rpy="0 0 0" xyz="0.14925 0 0.0775"/>
    <parent link="base_link"/>
    <child link="omni_ir_link"/>
    <axis xyz="0 0 0"/>
  </joint>
  <!--<link name="rear_wheel_link">
    <inertial>
      <origin xyz="0 0 0"/>
      <mass value="0.001" />
      <inertia ixx="0.0001" ixy="0.0" ixz="0.0" iyy="0.0001" iyz="0.0" izz="0.0001" />
    </inertial>

    <visual>
      <origin xyz="0 0 0" rpy="0 ${PI/2} ${PI/2}"/>
      <geometry>
        <sphere radius="0.015" />
      </geometry>
    </visual>

    <collision>
      <origin xyz="0 0 0" rpy="0 ${PI/2} ${PI/2}" />
      <geometry>
        <sphere radius="0.015" />
      </geometry>
    </collision>
    </link>
    <joint name="rear_castor_joint" type="fixed">
      <origin xyz="-0.13 0 0.0" rpy="0 0 0"/>
      <parent link="base_link"/>
      <child link="rear_wheel_link"/>
      <axis xyz="0 1 0"/>
    </joint>-->
  <link name="front_wheel_link">
    <inertial>
      <origin xyz="0 0 0"/>
      <mass value="0.01"/>
      <inertia ixx="0.001" ixy="0.0" ixz="0.0" iyy="0.001" iyz="0.0" izz="0.001"/>
    </inertial>
    <visual>
      <origin rpy="0 1.5707963267948966 1.5707963267948966" xyz="0 0 0"/>
      <geometry>
        <sphere radius="0.018"/>
      </geometry>
    </visual>
    <collision>
      <origin rpy="0 1.5707963267948966 1.5707963267948966" xyz="0 0 0"/>
      <geometry>
        <sphere radius="0.018"/>
      </geometry>
    </collision>
  </link>
  <!-- fixed because there's no transmission -->
  <joint name="front_castor_joint" type="fixed">
    <origin rpy="0 0 0" xyz="0.13 0 0.0"/>
    <parent link="base_link"/>
    <child link="front_wheel_link"/>
    <axis xyz="0 1 0"/>
  </joint>
  <joint name="gyro_joint" type="fixed">
    <axis xyz="0 1 0"/>
    <origin rpy="0 0 0" xyz="0 0 0.04"/>
    <parent link="base_link"/>
    <child link="gyro_link"/>
  </joint>
  <link name="gyro_link">
    <inertial>
      <mass value="0.001"/>
      <origin rpy="0 0 0" xyz="0 0 0"/>
      <inertia ixx="0.0001" ixy="0" ixz="0" iyy="0.000001" iyz="0" izz="0.0001"/>
    </inertial>
  </link>
  <gazebo>
    <plugin filename="libgazebo_ros_diff_drive.so" name="differential_drive_controller">
      <alwaysOn>true</alwaysOn>
      <updateRate>40</updateRate>
      <leftJoint>left_wheel_joint</leftJoint>
      <rightJoint>right_wheel_joint</rightJoint>
      <wheelSeparation>0.235</wheelSeparation>
      <wheelDiameter>0.072</wheelDiameter>
      <wheelTorque>1.0</wheelTorque>
      <!--wheelAcceleration>${wheel_accel}</wheelAcceleration-->
      <commandTopic>cmd_vel</commandTopic>
      <odometryTopic>odom</odometryTopic>
      <odometryFrame>odom</odometryFrame>
      <robotBaseFrame>base_footprint</robotBaseFrame>
      <publishWheelJointState>true</publishWheelJointState>
    </plugin>
    <plugin filename="libgazebo_ros_p3d.so" name="p3d_base_controller">
      <alwaysOn>true</alwaysOn>
      <updateRate>100.0</updateRate>
      <bodyName>base_link</bodyName>
      <topicName>simple_controller/absolute_position</topicName>
      <gaussianNoise>0</gaussianNoise>
      <frameName>map</frameName>
      <xyzOffsets>0 0 0</xyzOffsets>
      <rpyOffsets>0 0 0</rpyOffsets>
      <!--<interface:position name="p3d_base_position"/>-->
    </plugin>
  </gazebo>
  <gazebo reference="left_wheel_link">
    <mu1>1.0</mu1>
    <mu2>1.0</mu2>
    <kp>1000000.0</kp>
    <kd>100.0</kd>
    <minDepth>0.001</minDepth>
    <maxVel>1.0</maxVel>
  </gazebo>
  <gazebo reference="right_wheel_link">
    <mu1>1.0</mu1>
    <mu2>1.0</mu2>
    <kp>1000000.0</kp>
    <kd>100.0</kd>
    <minDepth>0.001</minDepth>
    <maxVel>1.0</maxVel>
  </gazebo>
  <gazebo reference="rear_wheel_link">
    <mu1>0.0</mu1>
    <mu2>0.0</mu2>
    <kp>1000000.0</kp>
    <kd>100.0</kd>
    <minDepth>0.001</minDepth>
    <maxVel>1.0</maxVel>
  </gazebo>
  <gazebo reference="front_wheel_link">
    <mu1>0.0</mu1>
    <mu2>0.0</mu2>
    <kp>1000000.0</kp>
    <kd>100.0</kd>
    <minDepth>0.001</minDepth>
    <maxVel>1.0</maxVel>
  </gazebo>
  <gazebo reference="wall_sensor_link">
    <sensor name="wall_sensor" type="ray">
      <always_on>true</always_on>
      <update_rate>20.0</update_rate>
      <pose>0 0 0 0 0 0</pose>
      <visualize>false</visualize>
      <ray>
        <scan>
          <horizontal>
            <samples>1</samples>
            <resolution>1</resolution>
            <min_angle>0</min_angle>
            <max_angle>0</max_angle>
          </horizontal>
        </scan>
        <range>
          <min>0.0160</min>
          <max>0.04</max>
          <resolution>0.1</resolution>
        </range>
      </ray>
    </sensor>
  </gazebo>
  <gazebo reference="left_cliff_sensor_link">
    <sensor name="left_cliff_sensor" type="ray">
      <always_on>true</always_on>
      <update_rate>20.0</update_rate>
      <pose>0 0 0 0 0 0</pose>
      <visualize>false</visualize>
      <ray>
        <scan>
          <horizontal>
            <samples>1</samples>
            <resolution>1</resolution>
            <min_angle>0</min_angle>
            <max_angle>0</max_angle>
          </horizontal>
        </scan>
        <range>
          <min>0.01</min>
          <max>0.04</max>
          <resolution>0.1</resolution>
        </range>
      </ray>
    </sensor>
  </gazebo>
  <gazebo reference="right_cliff_sensor_link">
    <sensor name="right_cliff_sensor" type="ray">
      <always_on>true</always_on>
      <update_rate>20.0</update_rate>
      <pose>0 0 0 0 0 0</pose>
      <visualize>false</visualize>
      <ray>
        <scan>
          <horizontal>
            <samples>1</samples>
            <resolution>1</resolution>
            <min_angle>0</min_angle>
            <max_angle>0</max_angle>
          </horizontal>
        </scan>
        <range>
          <min>0.01</min>
          <max>0.04</max>
          <resolution>0.1</resolution>
        </range>
      </ray>
    </sensor>
  </gazebo>
  <gazebo reference="leftfront_cliff_sensor_link">
    <sensor name="leftfront_cliff_sensor" type="ray">
      <always_on>true</always_on>
      <update_rate>20.0</update_rate>
      <pose>0 0 0 0 0 0</pose>
      <visualize>false</visualize>
      <ray>
        <scan>
          <horizontal>
            <samples>1</samples>
            <resolution>1</resolution>
            <min_angle>0</min_angle>
            <max_angle>0</max_angle>
          </horizontal>
        </scan>
        <range>
          <min>0.01</min>
          <max>0.04</max>
          <resolution>0.1</resolution>
        </range>
      </ray>
    </sensor>
  </gazebo>
  <gazebo reference="rightfront_cliff_sensor_link">
    <sensor name="rightfront_cliff_sensor" type="ray">
      <always_on>true</always_on>
      <update_rate>20.0</update_rate>
      <pose>0 0 0 0 0 0</pose>
      <visualize>false</visualize>
      <ray>
        <scan>
          <horizontal>
            <samples>1</samples>
            <resolution>1</resolution>
            <min_angle>0</min_angle>
            <max_angle>0</max_angle>
          </horizontal>
        </scan>
        <range>
          <min>0.01</min>
          <max>0.04</max>
          <resolution>0.1</resolution>
        </range>
      </ray>
    </sensor>
  </gazebo>
  <gazebo>
    <plugin filename="libgazebo_ros_imu.so" name="imu_controller">
      <alwaysOn>true</alwaysOn>
      <updateRate>30</updateRate>
      <bodyName>gyro_link</bodyName>
      <topicName>imu/data</topicName>
      <serviceName>imu/is_calibrated</serviceName>
      <gaussianNoise>2.89e-06</gaussianNoise>
      <xyzOffsets>0 0 0</xyzOffsets>
      <rpyOffsets>0 0 0</rpyOffsets>
    </plugin>
  </gazebo>
  <gazebo reference="bumper_link">
    <sensor name="sim_bumper" type="contact">
      <alwaysOn>true</alwaysOn>
      <updateRate>1000.0</updateRate>
      <material>Gazebo/Red</material>
      <contact>
        <collision>base_footprint_fixed_joint_lump__bumper_link_collision_collision_2</collision>
      </contact>
      <plugin filename="libgazebo_ros_bumper.so" name="gazebo_ros_bumper_controller">
        <bumperTopicName>bumper</bumperTopicName>
        <frameName>bumper_link</frameName>
      </plugin>
    </sensor>
  </gazebo>
</robot>
